<?xml version="1.0"?>
<robot name="allegro_hand_r">

  <material name="blue">
    <color rgba="0 0 0.8 1"/>
  </material>
  <material name="black">
    <color rgba="0 0 0 1"/>
  </material>
  <material name="white">
    <color rgba="1 1 1 1"/>
  </material>

  <link name="base_link">
    <visual>
      <geometry>
        <mesh filename="package://allegro_hand_model/meshes/40_10_link_g_r.stl"/>
      </geometry>
    </visual>
    <collision>
      <geometry>
        <mesh filename="package://allegro_hand_model/meshes/40_10_link_g_r.stl"/>
      </geometry>
    </collision>
    <inertial>
      <mass value="0.0041685782e+0.002"/>
      <inertia ixx="0.0011139612e+0.011" ixy="-0.0092906454e+0.010" ixz="0.0073970369e+0.009" 
      iyx= "-0.0092906454e+0.010" iyy="0.0046122500e+0.011" iyz="0.0049169085e+0.009" 
      izx = "0.0073970369e+0.009" izy = "0.0049169085e+0.009" izz="0.0057081991e+0.011"/>
    </inertial>
  </link>
  <!--Middle FInger-->
  <link name="mf1">
    <visual>
      <geometry>
        <mesh filename="package://allegro_hand_model/meshes/40_10_link_f1.stl"/>
      </geometry>
      <material name="blue"/>
      <origin xyz ="0 0 0.0166 "/>
    </visual>
    <collision>
      <geometry>
        <mesh filename="package://allegro_hand_model/meshes/40_10_link_f1.stl"/>
      </geometry>
      <origin xyz ="0 0 0.0166 "/>
    </collision>
    <inertial>
      <mass value="0.0011350110e+0.001" />
      <inertia ixx=" 0.0027007029e+0.003" ixy="0.0031772169e+00" ixz="-0.0099625685e+00" 
      iyx= "0.0031772169e+00" iyy=" 0.0020578543e+0.003" iyz="0.0041823243e+00" 
      izx = "-0.0099625685e+00" izy = "0.0041823243e+00" izz=" 0.0012713693e+0.003"/>
    </inertial>
  </link>
  <joint name="mf1" type="revolute">
    <parent link="base_link"/>
    <child link="mf1"/>
    <axis xyz="0 0 1"/>
    <origin xyz = "0 0 0"/>
    <limit lower="-0.57" upper="0.57" effort="10" velocity="3"/>
  </joint> 

  <link name="mf2">
    <visual>
      <geometry>
        <mesh filename="package://allegro_hand_model/meshes/40_10_link_f2.stl"/>
      </geometry>
      <material name="black"/>
      <origin rpy = "-1.5708 -1.5708 0" xyz ="0 0 0 "/>
    </visual>
    <collision>
      <geometry>
        <mesh filename="package://allegro_hand_model/meshes/40_10_link_f2.stl" />
      </geometry>
      <origin rpy = "-1.5708 -1.5708 0" xyz ="0 0 0 "/>
    </collision>
    <inertial>
      <mass value="0.0071189096e+0.001" />
      <inertia ixx="0.0010469372e+0.011" ixy="-0.0042436168e+0.010" ixz="-0.0018101962e+0.010" 
      iyx= "-0.0042436168e+0.010" iyy="0.0061027234e+0.011" iyz="0.0037248539e+0.009" 
      izx = " -0.0018101962e+0.010" izy = "0.0037248539e+0.009" izz=" 0.0057968823e+0.011"/>
    </inertial>
  </link>

  <joint name="mf2" type="revolute">
    <parent link="mf1"/>
    <child link="mf2"/>
    <origin xyz= "0 0 0.0166"/>
    <limit lower="-0.296" upper=" 1.71" effort="10" velocity="3"/>
    <axis xyz="0 1 0"/>
  </joint> 

  <link name="mf3">
    <visual>
      <geometry>
        <mesh filename="package://allegro_hand_model/meshes/40_10_link_f3.stl"/>
      </geometry>
      <material name="blue"/>
      <origin rpy = "-1.5708 0 0" xyz ="0 0 0 "/>
    </visual>
    <collision>
      <geometry>
        <mesh filename="package://allegro_hand_model/meshes/40_10_link_f3.stl" />
      </geometry>
      <origin rpy = "-1.5708 0 0" xyz ="0 0 0 "/>
    </collision>
    <inertial>
      <mass value="0.0037588606e+0.001" />
      <inertia ixx="  0.0046626681e+0.010" ixy="-0.0046540270e+0.010" ixz="0.0028462066e+0.009" 
      iyx= " -0.0046540270e+0.010" iyy=" 0.0015452396e+0.011" iyz="0.0012914215e+0.009" 
      izx = " 0.0028462066e+0.009" izy = "0.0012914215e+0.009" izz="0.0016359427e+0.011"/>
    </inertial>
  </link>

  <joint name="mf3" type="revolute">
    <parent link="mf2"/>
    <child link="mf3"/>
    <origin xyz= "0 0 0.054" rpy = "0 -1.5708 0"/>
    <limit lower="-0.274" upper=" 1.809" effort="10" velocity="3"/>
    <axis xyz="0 1 0"/>
  </joint> 

  <link name="mf4">
    <visual>
      <geometry>
        <mesh filename="package://allegro_hand_model/meshes/40_10_link_f4.stl"/>
      </geometry>
      <material name="black"/>
      <origin rpy = "-1.5708 0 0" xyz ="0 0 0 "/>
    </visual>
    <collision>
      <geometry>
        <mesh filename="package://allegro_hand_model/meshes/40_10_link_f4.stl" />
      </geometry>
      <origin rpy = "-1.5708 0 0" xyz ="0 0 0 "/>
    </collision>
    <inertial>
      <mass value="0.0094301124e+00" />
      <inertia ixx=" 0.0012117405e+0.003" ixy="0.0099624823e+00" ixz="0.0069119137e-0.001" 
      iyx= "0.0099624823e+00" iyy="  0.0021794983e+0.003" iyz="0.0031772815e+00" 
      izx = "0.0069119137e-0.001" izy = "0.0031772815e+00" izz=" 0.0015590472e+0.003"/>
    </inertial>
  </link>

  <joint name="mf4" type="revolute">
    <parent link="mf3"/>
    <child link="mf4"/>
    <origin xyz= "0.0384 0 0" rpy = "0 0 0"/>
    <limit lower="-0.327" upper="1.718" effort="10" velocity="3"/>
    <axis xyz="0 1 0"/>
  </joint> 

<link name="mf5">
    <visual>
      <geometry>
        <mesh filename="package://allegro_hand_model/meshes/40_10_link_f5.stl"/>
      </geometry>
      <material name="white"/>
      <origin rpy = "-1.5708 0 0" xyz ="0 0 0 "/>
    </visual>
    <collision>
      <geometry>
        <mesh filename="package://allegro_hand_model/meshes/40_10_link_f5.stl" />
      </geometry>
      <origin rpy = "-1.5708 0 0" xyz ="0 0 0 "/>
    </collision>
    <inertial>
      <mass value="0.0016654268e+0.001" />
      <inertia ixx=" 0.072993680e+0.001" ixy=" 0.0000000000e+00" ixz="0.0000000000e+00" 
      iyx= "0.0000000000e+00" iyy= "0.0011760891e+0.002" iyz="0.0000000000e+00" 
      izx = "0.0000000e+00" izy = "0.0000000e+00" izz="0.0010967651e+0.002"/>
    </inertial>
  </link>

  <joint name="mf5" type="fixed">
    <parent link="mf4"/>
    <child link="mf5"/>
    <origin xyz= "0.0157 0 0"/>
  </joint> 

<!--Pinky Finger-->
  <link name="pf1">
    <visual>
      <geometry>
        <mesh filename="package://allegro_hand_model/meshes/40_10_link_f1.stl"/>
      </geometry>
      <material name="blue"/>
    </visual>
    <collision>
      <geometry>
        <mesh filename="package://allegro_hand_model/meshes/40_10_link_f1.stl"/>
      </geometry>
    </collision>
    <inertial>
      <mass value="0.0011350110e+0.001" />
      <inertia ixx=" 0.0027007029e+0.003" ixy="0.0031772169e+00" ixz="-0.0099625685e+00" 
      iyx= "0.0031772169e+00" iyy=" 0.0020578543e+0.003" iyz="0.0041823243e+00" 
      izx = "-0.0099625685e+00" izy = "0.0041823243e+00" izz=" 0.0012713693e+0.003"/>
    </inertial>
  </link>
  <joint name="pf1" type="revolute">
    <parent link="base_link"/>
    <child link="pf1"/>
    <axis xyz="0 0 1"/>
    <origin rpy = "0.0872665 0 0" xyz ="0 -0.045098 0.014293 "/>
    <limit lower="-0.57" upper="0.57" effort="10" velocity="3"/>
  </joint>

  <link name="pf2">
    <visual>
      <geometry>
        <mesh filename="package://allegro_hand_model/meshes/40_10_link_f2.stl"/>
      </geometry>
      <material name="black"/>
      <origin rpy = " -1.5708  -1.5708 0" xyz ="0 0 0 "/>
    </visual>
    <collision>
      <geometry>
        <mesh filename="package://allegro_hand_model/meshes/40_10_link_f2.stl" />
      </geometry>
      <origin rpy = " -1.5708  -1.5708 0" xyz ="0 0 0 "/>
    </collision>
    <inertial>
      <mass value="0.0071189096e+0.001" />
      <inertia ixx="0.0010469372e+0.011" ixy="-0.0042436168e+0.010" ixz="-0.0018101962e+0.010" 
      iyx= "-0.0042436168e+0.010" iyy="0.0061027234e+0.011" iyz="0.0037248539e+0.009" 
      izx = " -0.0018101962e+0.010" izy = "0.0037248539e+0.009" izz=" 0.0057968823e+0.011"/>
    </inertial>
  </link>
  <joint name="pf2" type="revolute">
    <parent link="pf1"/>
    <child link="pf2"/>
    <origin rpy = "0 0 0" xyz ="0 0 0 "/>
    <limit lower="-0.296" upper="1.71" effort="10" velocity="3"/>
    <axis xyz="0 1 0"/>
  </joint> 
  

  <link name="pf3">
    <visual>
      <geometry>
        <mesh filename="package://allegro_hand_model/meshes/40_10_link_f3.stl"/>
      </geometry>
      <material name="blue"/>
      <origin rpy = "-1.5708 0 0" xyz ="0 0 0 "/>
    </visual>
    <collision>
      <geometry>
        <mesh filename="package://allegro_hand_model/meshes/40_10_link_f3.stl" />
      </geometry>
      <origin rpy = "-1.5708 0 0" xyz ="0 0 0 "/>
    </collision>
    <inertial>
      <mass value="0.0037588606e+0.001" />
      <inertia ixx="  0.0046626681e+0.010" ixy="-0.0046540270e+0.010" ixz="0.0028462066e+0.009" 
      iyx= " -0.0046540270e+0.010" iyy=" 0.0015452396e+0.011" iyz="0.0012914215e+0.009" 
      izx = " 0.0028462066e+0.009" izy = "0.0012914215e+0.009" izz="0.0016359427e+0.011"/>
    </inertial>
  </link>

  <joint name="pf3" type="revolute">
    <parent link="pf2"/>
    <child link="pf3"/>
    <origin xyz= "0 0 0.054" rpy = "0 -1.5708 0"/>
    <limit lower="-0.274" upper="1.809" effort="10" velocity="3"/>
    <axis xyz="0 1 0"/>
  </joint> 

  <link name="pf4">
    <visual>
      <geometry>
        <mesh filename="package://allegro_hand_model/meshes/40_10_link_f4.stl"/>
      </geometry>
      <material name="black"/>
      <origin rpy = "-1.5708 0 0" xyz ="0 0 0 "/>
    </visual>
    <collision>
      <geometry>
        <mesh filename="package://allegro_hand_model/meshes/40_10_link_f4.stl" />
      </geometry>
      <origin rpy = "-1.5708 0 0" xyz ="0 0 0 "/>
    </collision>
    <inertial>
      <mass value="0.0094301124e+00" />
      <inertia ixx=" 0.0012117405e+0.003" ixy="0.0099624823e+00" ixz="0.0069119137e-0.001" 
      iyx= "0.0099624823e+00" iyy="  0.0021794983e+0.003" iyz="0.0031772815e+00" 
      izx = "0.0069119137e-0.001" izy = "0.0031772815e+00" izz=" 0.0015590472e+0.003"/>
    </inertial>
  </link>

  <joint name="pf4" type="revolute">
    <parent link="pf3"/>
    <child link="pf4"/>
    <origin xyz= "0.0384 0 0"/>
     <limit lower="-0.327" upper="1.718" effort="10" velocity="3"/>
    <axis xyz="0 1 0"/>
  </joint> 

  <link name="pf5">
    <visual>
      <geometry>
        <mesh filename="package://allegro_hand_model/meshes/40_10_link_f5.stl"/>
      </geometry>
      <material name="white"/>
      <origin rpy = "-1.5708 0 0" xyz ="0 0 0 "/>
    </visual>
    <collision>
      <geometry>
        <mesh filename="package://allegro_hand_model/meshes/40_10_link_f5.stl" />
      </geometry>
      <origin rpy = "-1.5708 0 0" xyz ="0 0 0 "/>
    </collision>
    <inertial>
      <mass value="0.0016654268e+0.001" />
      <inertia ixx=" 0.072993680e+0.001" ixy=" 0.0000000000e+00" ixz="0.0000000000e+00" 
      iyx= "0.0000000000e+00" iyy= "0.0011760891e+0.002" iyz="0.0000000000e+00" 
      izx = "0.0000000e+00" izy = "0.0000000e+00" izz="0.0010967651e+0.002"/>
    </inertial>
  </link>

  <joint name="pf5" type="fixed">
    <parent link="pf4"/>
    <child link="pf5"/>
    <origin xyz= "0.0157 0 0"/>
  </joint> 
<!--Index FInger-->

<link name="if1">
    <visual>
      <geometry>
        <mesh filename="package://allegro_hand_model/meshes/40_10_link_f1.stl"/>
      </geometry>
      <material name="blue"/>
    </visual>
    <collision>
      <geometry>
        <mesh filename="package://allegro_hand_model/meshes/40_10_link_f1.stl"/>
      </geometry>
    </collision>
    <inertial>
      <mass value="0.0011350110e+0.001" />
      <inertia ixx=" 0.0027007029e+0.003" ixy="0.0031772169e+00" ixz="-0.0099625685e+00" 
      iyx= "0.0031772169e+00" iyy=" 0.0020578543e+0.003" iyz="0.0041823243e+00" 
      izx = "-0.0099625685e+00" izy = "0.0041823243e+00" izz=" 0.0012713693e+0.003"/>
    </inertial>
  </link>
  <joint name="if1" type="revolute">
    <parent link="base_link"/>
    <child link="if1"/>
    <axis xyz="0 0 1"/>
    <origin rpy = "-0.0872665 0 0" xyz ="0 0.045098 0.014293 "/>
    <limit lower="-0.57" upper="0.57" effort="10" velocity="3"/>
  </joint>

<link name="if2">
    <visual>
      <geometry>
        <mesh filename="package://allegro_hand_model/meshes/40_10_link_f2.stl"/>
      </geometry>
      <material name="black"/>
      <origin rpy = " -1.5708  -1.5708 0" xyz ="0 0 0 "/>
    </visual>
    <collision>
      <geometry>
        <mesh filename="package://allegro_hand_model/meshes/40_10_link_f2.stl" />
      </geometry>
      <origin rpy = " -1.5708  -1.5708 0" xyz ="0 0 0 "/>
    </collision>
    <inertial>
      <mass value="0.0071189096e+0.001" />
      <inertia ixx="0.0010469372e+0.011" ixy="-0.0042436168e+0.010" ixz="-0.0018101962e+0.010" 
      iyx= "-0.0042436168e+0.010" iyy="0.0061027234e+0.011" iyz="0.0037248539e+0.009" 
      izx = " -0.0018101962e+0.010" izy = "0.0037248539e+0.009" izz=" 0.0057968823e+0.011"/>
    </inertial>
  </link>
  <joint name="if2" type="revolute">
    <parent link="if1"/>
    <child link="if2"/>
    <origin rpy = "0 0 0" xyz ="0 0 0 "/>
    <limit lower="-0.296" upper="1.71" effort="10" velocity="3"/>
    <axis xyz="0 1 0"/>
  </joint>

  <link name="if3">
    <visual>
      <geometry>
        <mesh filename="package://allegro_hand_model/meshes/40_10_link_f3.stl"/>
      </geometry>
      <material name="blue"/>
      <origin rpy = "-1.5708 0 0" xyz ="0 0 0 "/>
    </visual>
    <collision>
      <geometry>
        <mesh filename="package://allegro_hand_model/meshes/40_10_link_f3.stl" />
      </geometry>
      <origin rpy = "-1.5708 0 0" xyz ="0 0 0 "/>
    </collision>
    <inertial>
      <mass value="0.0037588606e+0.001" />
      <inertia ixx="  0.0046626681e+0.010" ixy="-0.0046540270e+0.010" ixz="0.0028462066e+0.009" 
      iyx= " -0.0046540270e+0.010" iyy=" 0.0015452396e+0.011" iyz="0.0012914215e+0.009" 
      izx = " 0.0028462066e+0.009" izy = "0.0012914215e+0.009" izz="0.0016359427e+0.011"/>
    </inertial>
  </link>

  <joint name="if3" type="revolute">
    <parent link="if2"/>
    <child link="if3"/>
    <origin xyz= "0 0 0.054" rpy = "0 -1.5708 0"/>
    <limit lower="-0.274" upper="1.809" effort="10" velocity="3"/>
    <axis xyz="0 1 0"/>
  </joint> 


  <link name="if4">
    <visual>
      <geometry>
        <mesh filename="package://allegro_hand_model/meshes/40_10_link_f4.stl"/>
      </geometry>
      <material name="black"/>
      <origin rpy = "-1.5708 0 0" xyz ="0 0 0 "/>
    </visual>
    <collision>
      <geometry>
        <mesh filename="package://allegro_hand_model/meshes/40_10_link_f4.stl" />
      </geometry>
      <origin rpy = "-1.5708 0 0" xyz ="0 0 0 "/>
    </collision>
    <inertial>
      <mass value="0.0094301124e+00" />
      <inertia ixx=" 0.0012117405e+0.003" ixy="0.0099624823e+00" ixz="0.0069119137e-0.001" 
      iyx= "0.0099624823e+00" iyy="  0.0021794983e+0.003" iyz="0.0031772815e+00" 
      izx = "0.0069119137e-0.001" izy = "0.0031772815e+00" izz=" 0.0015590472e+0.003"/>
    </inertial>
  </link>

  <joint name="if4" type="revolute">
    <parent link="if3"/>
    <child link="if4"/>
    <origin xyz= "0.0384 0 0"/>
     <limit lower="-0.327" upper="1.718" effort="10" velocity="3"/>
    <axis xyz="0 1 0"/>
  </joint>


  <link name="if5">
    <visual>
      <geometry>
        <mesh filename="package://allegro_hand_model/meshes/40_10_link_f5.stl"/>
      </geometry>
      <material name="white"/>
      <origin rpy = "-1.5708 0 0" xyz ="0 0 0 "/>
    </visual>
    <collision>
      <geometry>
        <mesh filename="package://allegro_hand_model/meshes/40_10_link_f5.stl" />
      </geometry>
      <origin rpy = "-1.5708 0 0" xyz ="0 0 0 "/>
    </collision>
    <inertial>
      <mass value="0.0016654268e+0.001" />
      <inertia ixx=" 0.072993680e+0.001" ixy=" 0.0000000000e+00" ixz="0.0000000000e+00" 
      iyx= "0.0000000000e+00" iyy= "0.0011760891e+0.002" iyz="0.0000000000e+00" 
      izx = "0.0000000e+00" izy = "0.0000000e+00" izz="0.0010967651e+0.002"/>
    </inertial>
  </link>

  <joint name="if5" type="fixed">
    <parent link="if4"/>
    <child link="if5"/>
    <origin xyz= "0.0157 0 0"/>
  </joint>




<!--Thumb-->
  <link name="th1">
    <visual>
      <geometry>
        <mesh filename="package://allegro_hand_model/meshes/40_10_link_t1_r.stl" scale = "0.001 0.001 0.001"/>
        <!-- <origin xyz ="-0.0182 0.016958 -0.073288 " /> -->
      </geometry>
      <material name="blue"/>
    </visual>
    <collision>
      <geometry>
        <mesh filename="package://allegro_hand_model/meshes/40_10_link_t1_r.stl"/>
      </geometry>
    </collision>
    <inertial>
      <mass value="0.0079809876e-0.002" />
      <inertia ixx="0.0011585993e+0.008" ixy=" -0.0012877480e+0.006" ixz="-0.0046980813e+0.007" 
      iyx= "-0.0012877480e+0.006" iyy=" 0.0014364829e+0.008" iyz="-0.0028936529e+0.006" 
      izx = "-0.0046980813e+0.007" izy = "-0.0028936529e+0.006" izz=" 0.0028012673e+0.007"/>
    </inertial>
  </link>

  <joint name="th1" type="revolute">
    <parent link="base_link"/>
    <child link="th1"/>
    <limit lower="0.36357" upper="1.4968" effort="10" velocity="3"/>
    <axis xyz="0 0 -1"/>
    <origin rpy = "-0.0872665 0 0" xyz ="-0.0182 0.016958 -0.073288 " />
  </joint>


  <link name="th2">
    <visual>
      <geometry>
        <mesh filename="package://allegro_hand_model/meshes/40_10_link_t2.stl" scale = "0.001 0.001 0.001"/>
      </geometry>
      <material name="black"/>
      <origin rpy = " -1.5708 -1.5708 0" xyz ="0 0 0 "/>
    </visual>
    <collision>
      <geometry>
        <mesh filename="package://allegro_hand_model/meshes/40_10_link_t2.stl" scale = "0.001 0.001 0.001"/>
      </geometry>
    </collision>
    <inertial>
      <mass value="0.0011350110e-0.002" />
      <inertia ixx="0.0027007029e+00" ixy=" 0.0031772015e-0.003" ixz="-0.0099625696e-0.003" 
      iyx= "0.0031772015e-0.003" iyy="0.0020578543e+00" iyz="0.0041823243e-0.003" 
      izx = "-0.0099625696e-0.003" izy = "0.0041823243e-0.003" izz=" 0.0012713693e+00"/>
    </inertial>
  </link>
  <joint name="th2" type="revolute">
    <parent link="th1"/>
    <child link="th2"/>
    <origin rpy = "0 0 0" xyz ="0.005 0.055189 0 "/>
    <limit lower="-0.20504289" upper="1.263" effort="10" velocity="3"/>
    <axis xyz="0 1 0"/>
    
  </joint>

  <link name="th3">
    <visual>
      <geometry>
        <mesh filename="package://allegro_hand_model/meshes/40_10_link_t3.stl"/>
      </geometry>
      <material name="black"/>
      <origin rpy = " 0  0 -1.5708" xyz ="0 0 0 "/>
    </visual>
    <collision>
      <geometry>
        <mesh filename="package://allegro_hand_model/meshes/40_10_link_t3.stl" />
      </geometry>
    </collision>
    <inertial>
      <mass value=" 0.0040206693e-0.002" />
      <inertia ixx=" 0.0027804865e+0.007" ixy="0.0013945030e+06" ixz="0.0000000e+00" 
      iyx= " 0.0013945030e+0.006" iyy="0.0073569085e+0.007" iyz=" 0.0017291527e+0.004" 
      izx = " 0.0000000e+00" izy = "0.0017291527e+0.004" izz="0.0063982627e+0.007"/>
    </inertial>
  </link>
  <joint name="th3" type="revolute">
    <parent link="th2"/>
    <child link="th3"/>
    <origin rpy = "0 0 0" xyz ="0 0 0 "/>
    <limit lower="-0.2897" upper="1.7440" effort="10" velocity="3"/>
    <axis xyz="1 0 0"/>
  </joint>

  <link name="th4">
    <visual>
      <geometry>
        <mesh filename="package://allegro_hand_model/meshes/40_10_link_t4.stl"/>
      </geometry>
      <material name="blue"/>
      <origin rpy = " 0  0 -1.5708" xyz ="0 0 0 "/>
    </visual>
    <collision>
      <geometry>
        <mesh filename="package://allegro_hand_model/meshes/40_10_link_t4.stl" />
      </geometry>
    </collision>
    <inertial>
      <mass value=" 0.0040750131e-0.002" />
      <inertia ixx=" 0.0027804864e+0.007" ixy=" 0.0013945020e+0.006" ixz="0.0000000e+00" 
      iyx= "  0.0013945020e+0.006" iyy="0.0073569079e+0.007" iyz="0.0017291521e+0.004" 
      izx = " 0.0000000e+00" izy = " 0.0017291521e+0.004" izz="0.0063982622e+0.007"/>
    </inertial>
  </link>
  <joint name="th4" type="revolute">
    <parent link="th3"/>
    <child link="th4"/>
    <origin rpy = "0 0 0" xyz ="0 0.051204 0 "/>
    <limit lower="-0.2622" upper="1.81991" effort="10" velocity="3"/>
    <axis xyz="1 0 0"/>
  </joint>

  <link name="th5">
    <visual>
      <geometry>
        <mesh filename="package://allegro_hand_model/meshes/40_10_link_f5.stl"/>
      </geometry>
      <material name="white"/>
      <origin rpy = " 0  0 1.5708" xyz ="0 0 0 "/>
    </visual>
    <collision>
      <geometry>
        <mesh filename="package://allegro_hand_model/meshes/40_10_link_f5.stl" />
      </geometry>
    </collision>
    <inertial>
      <mass value="0.0016654268e+0.001" />
      <inertia ixx=" 0.072993680e+0.001" ixy=" 0.0000000000e+00" ixz="0.0000000000e+00" 
      iyx= "0.0000000000e+00" iyy= "0.0011760891e+0.002" iyz="0.0000000000e+00" 
      izx = "0.0000000e+00" izy = "0.0000000e+00" izz="0.0010967651e+0.002"/>
    </inertial>
  </link>
  <joint name="th5" type="fixed">
    <parent link="th4"/>
    <child link="th5"/>
    <origin rpy = "0 -1.4835335 0" xyz ="0 0.0313 0 "/>
    
  </joint>


</robot>
